
[2017-04-06 03:54:28] Traceback (most recent call last):
  File "/home/mwestphall/anaconda3/lib/python3.5/site-packages/serial/serialposix.py", line 265, in open
    self.fd = os.open(self.portstr, os.O_RDWR | os.O_NOCTTY | os.O_NONBLOCK)
FileNotFoundError: [Errno 2] No such file or directory: '/dev/ttyACM0'

During handling of the above exception, another exception occurred:

Traceback (most recent call last):
  File "index.py", line 55, in <module>
    main()
  File "index.py", line 38, in main
    external = External()
  File "index.py", line 14, in __init__
    self.ser = SerialEcho(tty)
  File "/home/mwestphall/ardupy/ardupy_gui/echo.py", line 11, in __init__
    self.ser = serial.Serial(tty,timeout=3)
  File "/home/mwestphall/anaconda3/lib/python3.5/site-packages/serial/serialutil.py", line 240, in __init__
    self.open()
  File "/home/mwestphall/anaconda3/lib/python3.5/site-packages/serial/serialposix.py", line 268, in open
    raise SerialException(msg.errno, "could not open port {}: {}".format(self._port, msg))
serial.serialutil.SerialException: [Errno 2] could not open port /dev/ttyACM0: [Errno 2] No such file or directory: '/dev/ttyACM0'

